{"uid":"a158365ba2f00990","name":"should_fail","fullName":"qa-testing-utils.tests.self_tests.SelfTests#should_fail","historyId":"3a9547494cf63596f9c632e8155d0efb","time":{"start":1749531258886,"stop":1749531258886,"duration":0},"status":"skipped","statusMessage":"XFAIL tests a known failing assertion\n\nAssertionError: Assertion failed","statusTrace":"self = <tests.self_tests.SelfTests object at 0x7f7ac722b230>\n\n    @pytest.mark.xfail(reason=\"tests a known failing assertion\")\n    def should_fail(self):\n        # NOTE: failure description is:\n        # Assertion failed\n>       assert_that(False)\nE       AssertionError: Assertion failed\n\nqa-testing-utils/tests/self_tests.py:41: AssertionError","flaky":false,"newFailed":false,"newBroken":false,"newPassed":false,"retriesCount":0,"retriesStatusChange":false,"beforeStages":[{"name":"_xunit_setup_method_fixture_SelfTests","time":{"start":1749531258886,"stop":1749531258886,"duration":0},"status":"passed","steps":[],"attachments":[],"parameters":[],"shouldDisplayMessage":false,"stepsCount":0,"attachmentsCount":0,"hasContent":false,"attachmentStep":false}],"testStage":{"status":"skipped","statusMessage":"XFAIL tests a known failing assertion\n\nAssertionError: Assertion failed","statusTrace":"self = <tests.self_tests.SelfTests object at 0x7f7ac722b230>\n\n    @pytest.mark.xfail(reason=\"tests a known failing assertion\")\n    def should_fail(self):\n        # NOTE: failure description is:\n        # Assertion failed\n>       assert_that(False)\nE       AssertionError: Assertion failed\n\nqa-testing-utils/tests/self_tests.py:41: AssertionError","steps":[],"attachments":[{"uid":"cb271f2c70714377","name":"log","source":"cb271f2c70714377.txt","type":"text/plain","size":272}],"parameters":[],"shouldDisplayMessage":true,"stepsCount":0,"attachmentsCount":1,"hasContent":true,"attachmentStep":false},"afterStages":[{"name":"_xunit_setup_method_fixture_SelfTests::0","time":{"start":1749531258943,"stop":1749531258944,"duration":1},"status":"passed","steps":[],"attachments":[],"parameters":[],"shouldDisplayMessage":false,"stepsCount":0,"attachmentsCount":0,"hasContent":false,"attachmentStep":false}],"labels":[{"name":"tag","value":"@pytest.mark.xfail(reason='tests a known failing assertion')"},{"name":"parentSuite","value":"qa-testing-utils.tests"},{"name":"suite","value":"self_tests"},{"name":"subSuite","value":"SelfTests"},{"name":"host","value":"pkrvmf6wy0o8zjz"},{"name":"thread","value":"2965-MainThread"},{"name":"framework","value":"pytest"},{"name":"language","value":"cpython3"},{"name":"package","value":"qa-testing-utils.tests.self_tests"},{"name":"resultFormat","value":"allure2"}],"parameters":[],"links":[],"hidden":false,"retry":false,"extra":{"severity":"normal","retries":[],"categories":[],"tags":["@pytest.mark.xfail(reason='tests a known failing assertion')"]},"source":"a158365ba2f00990.json","parameterValues":[]}