ERROR    root:exception_utils.py:29 Exception occurred: trouble
Traceback (most recent call last):
  File "/home/runner/work/qa-automation-python/qa-automation-python/qa-testing-utils/src/qa_testing_utils/exception_utils.py", line 27, in safely
    return Some(supplier())
                ~~~~~~~~^^
  File "/home/runner/work/qa-automation-python/qa-automation-python/qa-testing-utils/tests/exception_utils_tests.py", line 14, in <lambda>
    assert safely(lambda: trouble(7)).value_or("nada") == "nada"
                          ~~~~~~~^^^
  File "/home/runner/work/qa-automation-python/qa-automation-python/qa-testing-utils/tests/exception_utils_tests.py", line 12, in trouble
    raise Exception("trouble")
Exception: trouble